[2024-10-26T07:34:55.156+0000] {local_task_job_runner.py:120} INFO - ::group::Pre task execution logs
[2024-10-26T07:34:55.204+0000] {taskinstance.py:2076} INFO - Dependencies all met for dep_context=non-requeueable deps ti=<TaskInstance: e_commerce_dw_etl.transform_dim_dates scheduled__2024-03-01T00:00:00+00:00 [queued]>
[2024-10-26T07:34:55.219+0000] {taskinstance.py:2076} INFO - Dependencies all met for dep_context=requeueable deps ti=<TaskInstance: e_commerce_dw_etl.transform_dim_dates scheduled__2024-03-01T00:00:00+00:00 [queued]>
[2024-10-26T07:34:55.220+0000] {taskinstance.py:2306} INFO - Starting attempt 2 of 2
[2024-10-26T07:34:55.253+0000] {taskinstance.py:2330} INFO - Executing <Task(PythonOperator): transform_dim_dates> on 2024-03-01 00:00:00+00:00
[2024-10-26T07:34:55.264+0000] {standard_task_runner.py:63} INFO - Started process 466 to run task
[2024-10-26T07:34:55.269+0000] {standard_task_runner.py:90} INFO - Running: ['***', 'tasks', 'run', 'e_commerce_dw_etl', 'transform_dim_dates', 'scheduled__2024-03-01T00:00:00+00:00', '--job-id', '681', '--raw', '--subdir', 'DAGS_FOLDER/e_commerce_dw_dag.py', '--cfg-path', '/tmp/tmp6op9t82a']
[2024-10-26T07:34:55.272+0000] {standard_task_runner.py:91} INFO - Job 681: Subtask transform_dim_dates
[2024-10-26T07:34:55.352+0000] {task_command.py:426} INFO - Running <TaskInstance: e_commerce_dw_etl.transform_dim_dates scheduled__2024-03-01T00:00:00+00:00 [running]> on host eed3011aebc3
[2024-10-26T07:34:55.497+0000] {taskinstance.py:2648} INFO - Exporting env vars: AIRFLOW_CTX_DAG_OWNER='***' AIRFLOW_CTX_DAG_ID='e_commerce_dw_etl' AIRFLOW_CTX_TASK_ID='transform_dim_dates' AIRFLOW_CTX_EXECUTION_DATE='2024-03-01T00:00:00+00:00' AIRFLOW_CTX_TRY_NUMBER='2' AIRFLOW_CTX_DAG_RUN_ID='scheduled__2024-03-01T00:00:00+00:00'
[2024-10-26T07:34:55.498+0000] {taskinstance.py:430} INFO - ::endgroup::
[2024-10-26T07:34:55.521+0000] {taskinstance.py:441} INFO - ::group::Post task execution logs
[2024-10-26T07:34:55.522+0000] {taskinstance.py:2905} ERROR - Task failed with exception
Traceback (most recent call last):
  File "/home/airflow/.local/lib/python3.10/site-packages/airflow/models/taskinstance.py", line 465, in _execute_task
    result = _execute_callable(context=context, **execute_callable_kwargs)
  File "/home/airflow/.local/lib/python3.10/site-packages/airflow/models/taskinstance.py", line 432, in _execute_callable
    return execute_callable(context=context, **execute_callable_kwargs)
  File "/home/airflow/.local/lib/python3.10/site-packages/airflow/models/baseoperator.py", line 401, in wrapper
    return func(self, *args, **kwargs)
  File "/home/airflow/.local/lib/python3.10/site-packages/airflow/operators/python.py", line 235, in execute
    return_value = self.execute_callable()
  File "/home/airflow/.local/lib/python3.10/site-packages/airflow/operators/python.py", line 252, in execute_callable
    return self.python_callable(*self.op_args, **self.op_kwargs)
  File "/opt/airflow/dags/transform_dim_dates.py", line 5, in transform_dim_dates
    warehouse_operator = PostgresOperator('postgres')
NameError: name 'PostgresOperator' is not defined
[2024-10-26T07:34:55.541+0000] {taskinstance.py:1206} INFO - Marking task as FAILED. dag_id=e_commerce_dw_etl, task_id=transform_dim_dates, run_id=scheduled__2024-03-01T00:00:00+00:00, execution_date=20240301T000000, start_date=20241026T073455, end_date=20241026T073455
[2024-10-26T07:34:55.580+0000] {standard_task_runner.py:110} ERROR - Failed to execute job 681 for task transform_dim_dates (name 'PostgresOperator' is not defined; 466)
[2024-10-26T07:34:55.603+0000] {local_task_job_runner.py:240} INFO - Task exited with return code 1
[2024-10-26T07:34:55.645+0000] {taskinstance.py:3503} INFO - 0 downstream tasks scheduled from follow-on schedule check
[2024-10-26T07:34:55.652+0000] {local_task_job_runner.py:222} INFO - ::endgroup::
