[2024-10-26T07:33:56.425+0000] {local_task_job_runner.py:120} INFO - ::group::Pre task execution logs
[2024-10-26T07:33:56.478+0000] {taskinstance.py:2076} INFO - Dependencies all met for dep_context=non-requeueable deps ti=<TaskInstance: e_commerce_dw_etl.transform_dim_sellers scheduled__2024-02-23T00:00:00+00:00 [queued]>
[2024-10-26T07:33:56.496+0000] {taskinstance.py:2076} INFO - Dependencies all met for dep_context=requeueable deps ti=<TaskInstance: e_commerce_dw_etl.transform_dim_sellers scheduled__2024-02-23T00:00:00+00:00 [queued]>
[2024-10-26T07:33:56.498+0000] {taskinstance.py:2306} INFO - Starting attempt 2 of 2
[2024-10-26T07:33:56.537+0000] {taskinstance.py:2330} INFO - Executing <Task(PythonOperator): transform_dim_sellers> on 2024-02-23 00:00:00+00:00
[2024-10-26T07:33:56.549+0000] {standard_task_runner.py:63} INFO - Started process 362 to run task
[2024-10-26T07:33:56.553+0000] {standard_task_runner.py:90} INFO - Running: ['***', 'tasks', 'run', 'e_commerce_dw_etl', 'transform_dim_sellers', 'scheduled__2024-02-23T00:00:00+00:00', '--job-id', '638', '--raw', '--subdir', 'DAGS_FOLDER/e_commerce_dw_dag.py', '--cfg-path', '/tmp/tmp66iupnct']
[2024-10-26T07:33:56.556+0000] {standard_task_runner.py:91} INFO - Job 638: Subtask transform_dim_sellers
[2024-10-26T07:33:56.627+0000] {task_command.py:426} INFO - Running <TaskInstance: e_commerce_dw_etl.transform_dim_sellers scheduled__2024-02-23T00:00:00+00:00 [running]> on host eed3011aebc3
[2024-10-26T07:33:56.746+0000] {taskinstance.py:2648} INFO - Exporting env vars: AIRFLOW_CTX_DAG_OWNER='***' AIRFLOW_CTX_DAG_ID='e_commerce_dw_etl' AIRFLOW_CTX_TASK_ID='transform_dim_sellers' AIRFLOW_CTX_EXECUTION_DATE='2024-02-23T00:00:00+00:00' AIRFLOW_CTX_TRY_NUMBER='2' AIRFLOW_CTX_DAG_RUN_ID='scheduled__2024-02-23T00:00:00+00:00'
[2024-10-26T07:33:56.748+0000] {taskinstance.py:430} INFO - ::endgroup::
[2024-10-26T07:33:56.774+0000] {base.py:84} INFO - Using connection ID 'postgres' for task execution.
[2024-10-26T07:33:56.794+0000] {logging_mixin.py:188} WARNING - /home/***/.local/lib/python3.10/site-packages/***/providers/common/sql/hooks/sql.py:263 UserWarning: pandas only supports SQLAlchemy connectable (engine/connection) or database string URI or sqlite3 DBAPI2 connection. Other DBAPI2 objects are not tested. Please consider using SQLAlchemy.
[2024-10-26T07:33:56.803+0000] {taskinstance.py:441} INFO - ::group::Post task execution logs
[2024-10-26T07:33:56.804+0000] {taskinstance.py:2905} ERROR - Task failed with exception
Traceback (most recent call last):
  File "/home/airflow/.local/lib/python3.10/site-packages/pandas/io/sql.py", line 2018, in execute
    cur.execute(*args, **kwargs)
psycopg2.errors.UndefinedTable: relation "staging.stg_sellers" does not exist
LINE 1: SELECT * FROM staging.stg_sellers
                      ^


The above exception was the direct cause of the following exception:

Traceback (most recent call last):
  File "/home/airflow/.local/lib/python3.10/site-packages/airflow/models/taskinstance.py", line 465, in _execute_task
    result = _execute_callable(context=context, **execute_callable_kwargs)
  File "/home/airflow/.local/lib/python3.10/site-packages/airflow/models/taskinstance.py", line 432, in _execute_callable
    return execute_callable(context=context, **execute_callable_kwargs)
  File "/home/airflow/.local/lib/python3.10/site-packages/airflow/models/baseoperator.py", line 401, in wrapper
    return func(self, *args, **kwargs)
  File "/home/airflow/.local/lib/python3.10/site-packages/airflow/operators/python.py", line 235, in execute
    return_value = self.execute_callable()
  File "/home/airflow/.local/lib/python3.10/site-packages/airflow/operators/python.py", line 252, in execute_callable
    return self.python_callable(*self.op_args, **self.op_kwargs)
  File "/opt/airflow/dags/transform_dim_sellers.py", line 10, in transform_dim_sellers
    df = staging_operator.get_data_to_pd("SELECT * FROM staging.stg_sellers")
  File "/opt/airflow/plugins/postgresql_operator.py", line 14, in get_data_to_pd
    return self.hook.get_pandas_df(sql)
  File "/home/airflow/.local/lib/python3.10/site-packages/airflow/providers/common/sql/hooks/sql.py", line 263, in get_pandas_df
    return psql.read_sql(sql, con=conn, params=parameters, **kwargs)
  File "/home/airflow/.local/lib/python3.10/site-packages/pandas/io/sql.py", line 564, in read_sql
    return pandas_sql.read_query(
  File "/home/airflow/.local/lib/python3.10/site-packages/pandas/io/sql.py", line 2078, in read_query
    cursor = self.execute(*args)
  File "/home/airflow/.local/lib/python3.10/site-packages/pandas/io/sql.py", line 2030, in execute
    raise ex from exc
pandas.errors.DatabaseError: Execution failed on sql 'SELECT * FROM staging.stg_sellers': relation "staging.stg_sellers" does not exist
LINE 1: SELECT * FROM staging.stg_sellers
                      ^

[2024-10-26T07:33:56.828+0000] {taskinstance.py:1206} INFO - Marking task as FAILED. dag_id=e_commerce_dw_etl, task_id=transform_dim_sellers, run_id=scheduled__2024-02-23T00:00:00+00:00, execution_date=20240223T000000, start_date=20241026T073356, end_date=20241026T073356
[2024-10-26T07:33:56.844+0000] {standard_task_runner.py:110} ERROR - Failed to execute job 638 for task transform_dim_sellers (Execution failed on sql 'SELECT * FROM staging.stg_sellers': relation "staging.stg_sellers" does not exist
LINE 1: SELECT * FROM staging.stg_sellers
                      ^
; 362)
[2024-10-26T07:33:56.888+0000] {local_task_job_runner.py:240} INFO - Task exited with return code 1
[2024-10-26T07:33:56.898+0000] {local_task_job_runner.py:222} INFO - ::endgroup::
