[2024-10-26T07:54:47.532+0000] {local_task_job_runner.py:120} INFO - ::group::Pre task execution logs
[2024-10-26T07:54:47.646+0000] {taskinstance.py:2076} INFO - Dependencies all met for dep_context=non-requeueable deps ti=<TaskInstance: e_commerce_dw_etl.transform_fact_orders manual__2024-10-26T07:54:35.648807+00:00 [queued]>
[2024-10-26T07:54:47.659+0000] {taskinstance.py:2076} INFO - Dependencies all met for dep_context=requeueable deps ti=<TaskInstance: e_commerce_dw_etl.transform_fact_orders manual__2024-10-26T07:54:35.648807+00:00 [queued]>
[2024-10-26T07:54:47.660+0000] {taskinstance.py:2306} INFO - Starting attempt 1 of 1
[2024-10-26T07:54:47.679+0000] {taskinstance.py:2330} INFO - Executing <Task(PythonOperator): transform_fact_orders> on 2024-10-26 07:54:35.648807+00:00
[2024-10-26T07:54:47.685+0000] {standard_task_runner.py:63} INFO - Started process 1170 to run task
[2024-10-26T07:54:47.687+0000] {standard_task_runner.py:90} INFO - Running: ['***', 'tasks', 'run', 'e_commerce_dw_etl', 'transform_fact_orders', 'manual__2024-10-26T07:54:35.648807+00:00', '--job-id', '713', '--raw', '--subdir', 'DAGS_FOLDER/e_commerce_dw_dag.py', '--cfg-path', '/tmp/tmpbtoli6tk']
[2024-10-26T07:54:47.689+0000] {standard_task_runner.py:91} INFO - Job 713: Subtask transform_fact_orders
[2024-10-26T07:54:47.743+0000] {task_command.py:426} INFO - Running <TaskInstance: e_commerce_dw_etl.transform_fact_orders manual__2024-10-26T07:54:35.648807+00:00 [running]> on host eed3011aebc3
[2024-10-26T07:54:47.839+0000] {taskinstance.py:2648} INFO - Exporting env vars: AIRFLOW_CTX_DAG_OWNER='***' AIRFLOW_CTX_DAG_ID='e_commerce_dw_etl' AIRFLOW_CTX_TASK_ID='transform_fact_orders' AIRFLOW_CTX_EXECUTION_DATE='2024-10-26T07:54:35.648807+00:00' AIRFLOW_CTX_TRY_NUMBER='1' AIRFLOW_CTX_DAG_RUN_ID='manual__2024-10-26T07:54:35.648807+00:00'
[2024-10-26T07:54:47.841+0000] {taskinstance.py:430} INFO - ::endgroup::
[2024-10-26T07:54:47.862+0000] {base.py:84} INFO - Using connection ID 'postgres' for task execution.
[2024-10-26T07:54:47.880+0000] {logging_mixin.py:188} WARNING - /home/***/.local/lib/python3.10/site-packages/***/providers/common/sql/hooks/sql.py:263 UserWarning: pandas only supports SQLAlchemy connectable (engine/connection) or database string URI or sqlite3 DBAPI2 connection. Other DBAPI2 objects are not tested. Please consider using SQLAlchemy.
[2024-10-26T07:54:48.808+0000] {base.py:84} INFO - Using connection ID 'postgres' for task execution.
[2024-10-26T07:54:48.819+0000] {logging_mixin.py:188} WARNING - /home/***/.local/lib/python3.10/site-packages/***/providers/common/sql/hooks/sql.py:263 UserWarning: pandas only supports SQLAlchemy connectable (engine/connection) or database string URI or sqlite3 DBAPI2 connection. Other DBAPI2 objects are not tested. Please consider using SQLAlchemy.
[2024-10-26T07:54:49.899+0000] {base.py:84} INFO - Using connection ID 'postgres' for task execution.
[2024-10-26T07:54:49.910+0000] {logging_mixin.py:188} WARNING - /home/***/.local/lib/python3.10/site-packages/***/providers/common/sql/hooks/sql.py:263 UserWarning: pandas only supports SQLAlchemy connectable (engine/connection) or database string URI or sqlite3 DBAPI2 connection. Other DBAPI2 objects are not tested. Please consider using SQLAlchemy.
[2024-10-26T07:54:51.036+0000] {taskinstance.py:441} INFO - ::group::Post task execution logs
[2024-10-26T07:54:51.037+0000] {taskinstance.py:2905} ERROR - Task failed with exception
Traceback (most recent call last):
  File "/home/airflow/.local/lib/python3.10/site-packages/pandas/core/indexes/base.py", line 3802, in get_loc
    return self._engine.get_loc(casted_key)
  File "pandas/_libs/index.pyx", line 138, in pandas._libs.index.IndexEngine.get_loc
  File "pandas/_libs/index.pyx", line 165, in pandas._libs.index.IndexEngine.get_loc
  File "pandas/_libs/hashtable_class_helper.pxi", line 5745, in pandas._libs.hashtable.PyObjectHashTable.get_item
  File "pandas/_libs/hashtable_class_helper.pxi", line 5753, in pandas._libs.hashtable.PyObjectHashTable.get_item
KeyError: 'customer_zip_code_prefix'

The above exception was the direct cause of the following exception:

Traceback (most recent call last):
  File "/home/airflow/.local/lib/python3.10/site-packages/airflow/models/taskinstance.py", line 465, in _execute_task
    result = _execute_callable(context=context, **execute_callable_kwargs)
  File "/home/airflow/.local/lib/python3.10/site-packages/airflow/models/taskinstance.py", line 432, in _execute_callable
    return execute_callable(context=context, **execute_callable_kwargs)
  File "/home/airflow/.local/lib/python3.10/site-packages/airflow/models/baseoperator.py", line 401, in wrapper
    return func(self, *args, **kwargs)
  File "/home/airflow/.local/lib/python3.10/site-packages/airflow/operators/python.py", line 235, in execute
    return_value = self.execute_callable()
  File "/home/airflow/.local/lib/python3.10/site-packages/airflow/operators/python.py", line 252, in execute_callable
    return self.python_callable(*self.op_args, **self.op_kwargs)
  File "/opt/airflow/dags/transform_fact_orders.py", line 35, in transform_fact_orders
    df['geolocation_key'] = df['customer_zip_code_prefix']
  File "/home/airflow/.local/lib/python3.10/site-packages/pandas/core/frame.py", line 3807, in __getitem__
    indexer = self.columns.get_loc(key)
  File "/home/airflow/.local/lib/python3.10/site-packages/pandas/core/indexes/base.py", line 3804, in get_loc
    raise KeyError(key) from err
KeyError: 'customer_zip_code_prefix'
[2024-10-26T07:54:51.069+0000] {taskinstance.py:1206} INFO - Marking task as FAILED. dag_id=e_commerce_dw_etl, task_id=transform_fact_orders, run_id=manual__2024-10-26T07:54:35.648807+00:00, execution_date=20241026T075435, start_date=20241026T075447, end_date=20241026T075451
[2024-10-26T07:54:51.086+0000] {standard_task_runner.py:110} ERROR - Failed to execute job 713 for task transform_fact_orders ('customer_zip_code_prefix'; 1170)
[2024-10-26T07:54:51.123+0000] {local_task_job_runner.py:240} INFO - Task exited with return code 1
[2024-10-26T07:54:51.142+0000] {taskinstance.py:3503} INFO - 0 downstream tasks scheduled from follow-on schedule check
[2024-10-26T07:54:51.145+0000] {local_task_job_runner.py:222} INFO - ::endgroup::
