[2024-10-26T07:22:07.730+0000] {local_task_job_runner.py:120} INFO - ::group::Pre task execution logs
[2024-10-26T07:22:07.877+0000] {taskinstance.py:2076} INFO - Dependencies all met for dep_context=non-requeueable deps ti=<TaskInstance: e_commerce_dw_etl.transform_dim_geolocation scheduled__2024-01-08T00:00:00+00:00 [queued]>
[2024-10-26T07:22:07.901+0000] {taskinstance.py:2076} INFO - Dependencies all met for dep_context=requeueable deps ti=<TaskInstance: e_commerce_dw_etl.transform_dim_geolocation scheduled__2024-01-08T00:00:00+00:00 [queued]>
[2024-10-26T07:22:07.904+0000] {taskinstance.py:2306} INFO - Starting attempt 2 of 2
[2024-10-26T07:22:07.952+0000] {taskinstance.py:2330} INFO - Executing <Task(PythonOperator): transform_dim_geolocation> on 2024-01-08 00:00:00+00:00
[2024-10-26T07:22:07.978+0000] {standard_task_runner.py:63} INFO - Started process 711 to run task
[2024-10-26T07:22:07.985+0000] {standard_task_runner.py:90} INFO - Running: ['***', 'tasks', 'run', 'e_commerce_dw_etl', 'transform_dim_geolocation', 'scheduled__2024-01-08T00:00:00+00:00', '--job-id', '212', '--raw', '--subdir', 'DAGS_FOLDER/e_commerce_dw_dag.py', '--cfg-path', '/tmp/tmp7nagjzc2']
[2024-10-26T07:22:07.995+0000] {standard_task_runner.py:91} INFO - Job 212: Subtask transform_dim_geolocation
[2024-10-26T07:22:08.167+0000] {task_command.py:426} INFO - Running <TaskInstance: e_commerce_dw_etl.transform_dim_geolocation scheduled__2024-01-08T00:00:00+00:00 [running]> on host eed3011aebc3
[2024-10-26T07:22:08.394+0000] {taskinstance.py:2648} INFO - Exporting env vars: AIRFLOW_CTX_DAG_OWNER='***' AIRFLOW_CTX_DAG_ID='e_commerce_dw_etl' AIRFLOW_CTX_TASK_ID='transform_dim_geolocation' AIRFLOW_CTX_EXECUTION_DATE='2024-01-08T00:00:00+00:00' AIRFLOW_CTX_TRY_NUMBER='2' AIRFLOW_CTX_DAG_RUN_ID='scheduled__2024-01-08T00:00:00+00:00'
[2024-10-26T07:22:08.397+0000] {taskinstance.py:430} INFO - ::endgroup::
[2024-10-26T07:22:08.537+0000] {taskinstance.py:441} INFO - ::group::Post task execution logs
[2024-10-26T07:22:08.599+0000] {taskinstance.py:2905} ERROR - Task failed with exception
Traceback (most recent call last):
  File "/home/airflow/.local/lib/python3.10/site-packages/airflow/models/taskinstance.py", line 465, in _execute_task
    result = _execute_callable(context=context, **execute_callable_kwargs)
  File "/home/airflow/.local/lib/python3.10/site-packages/airflow/models/taskinstance.py", line 432, in _execute_callable
    return execute_callable(context=context, **execute_callable_kwargs)
  File "/home/airflow/.local/lib/python3.10/site-packages/airflow/models/baseoperator.py", line 401, in wrapper
    return func(self, *args, **kwargs)
  File "/home/airflow/.local/lib/python3.10/site-packages/airflow/operators/python.py", line 235, in execute
    return_value = self.execute_callable()
  File "/home/airflow/.local/lib/python3.10/site-packages/airflow/operators/python.py", line 252, in execute_callable
    return self.python_callable(*self.op_args, **self.op_kwargs)
  File "/opt/airflow/dags/transform_dim_geolocation.py", line 10, in transform_dim_geolocation
    df = staging_operator.get_data_to_pd("SELECT * FROM staging.stg_geolocation")
  File "/opt/airflow/plugins/postgresql_operator.py", line 14, in get_data_to_pd
    return self.hook.get_pandas_df(sql)
  File "/home/airflow/.local/lib/python3.10/site-packages/airflow/providers/common/sql/hooks/sql.py", line 262, in get_pandas_df
    with closing(self.get_conn()) as conn:
  File "/home/airflow/.local/lib/python3.10/site-packages/airflow/providers/postgres/hooks/postgres.py", line 145, in get_conn
    conn = deepcopy(self.connection or self.get_connection(conn_id))
  File "/home/airflow/.local/lib/python3.10/site-packages/airflow/hooks/base.py", line 83, in get_connection
    conn = Connection.get_connection_from_secrets(conn_id)
  File "/home/airflow/.local/lib/python3.10/site-packages/airflow/models/connection.py", line 519, in get_connection_from_secrets
    raise AirflowNotFoundException(f"The conn_id `{conn_id}` isn't defined")
airflow.exceptions.AirflowNotFoundException: The conn_id `postgres_staging` isn't defined
[2024-10-26T07:22:08.637+0000] {taskinstance.py:1206} INFO - Marking task as FAILED. dag_id=e_commerce_dw_etl, task_id=transform_dim_geolocation, run_id=scheduled__2024-01-08T00:00:00+00:00, execution_date=20240108T000000, start_date=20241026T072207, end_date=20241026T072208
[2024-10-26T07:22:08.677+0000] {standard_task_runner.py:110} ERROR - Failed to execute job 212 for task transform_dim_geolocation (The conn_id `postgres_staging` isn't defined; 711)
[2024-10-26T07:22:08.733+0000] {local_task_job_runner.py:240} INFO - Task exited with return code 1
[2024-10-26T07:22:08.809+0000] {taskinstance.py:3503} INFO - 0 downstream tasks scheduled from follow-on schedule check
[2024-10-26T07:22:08.822+0000] {local_task_job_runner.py:222} INFO - ::endgroup::
