[2024-10-26T07:22:25.279+0000] {local_task_job_runner.py:120} INFO - ::group::Pre task execution logs
[2024-10-26T07:22:25.402+0000] {taskinstance.py:2076} INFO - Dependencies all met for dep_context=non-requeueable deps ti=<TaskInstance: e_commerce_dw_etl.transform_dim_customers scheduled__2024-01-27T00:00:00+00:00 [queued]>
[2024-10-26T07:22:25.427+0000] {taskinstance.py:2076} INFO - Dependencies all met for dep_context=requeueable deps ti=<TaskInstance: e_commerce_dw_etl.transform_dim_customers scheduled__2024-01-27T00:00:00+00:00 [queued]>
[2024-10-26T07:22:25.430+0000] {taskinstance.py:2306} INFO - Starting attempt 1 of 2
[2024-10-26T07:22:25.512+0000] {taskinstance.py:2330} INFO - Executing <Task(PythonOperator): transform_dim_customers> on 2024-01-27 00:00:00+00:00
[2024-10-26T07:22:25.525+0000] {standard_task_runner.py:63} INFO - Started process 946 to run task
[2024-10-26T07:22:25.531+0000] {standard_task_runner.py:90} INFO - Running: ['***', 'tasks', 'run', 'e_commerce_dw_etl', 'transform_dim_customers', 'scheduled__2024-01-27T00:00:00+00:00', '--job-id', '326', '--raw', '--subdir', 'DAGS_FOLDER/e_commerce_dw_dag.py', '--cfg-path', '/tmp/tmp0aou0ofx']
[2024-10-26T07:22:25.535+0000] {standard_task_runner.py:91} INFO - Job 326: Subtask transform_dim_customers
[2024-10-26T07:22:25.662+0000] {task_command.py:426} INFO - Running <TaskInstance: e_commerce_dw_etl.transform_dim_customers scheduled__2024-01-27T00:00:00+00:00 [running]> on host eed3011aebc3
[2024-10-26T07:22:25.847+0000] {taskinstance.py:2648} INFO - Exporting env vars: AIRFLOW_CTX_DAG_OWNER='***' AIRFLOW_CTX_DAG_ID='e_commerce_dw_etl' AIRFLOW_CTX_TASK_ID='transform_dim_customers' AIRFLOW_CTX_EXECUTION_DATE='2024-01-27T00:00:00+00:00' AIRFLOW_CTX_TRY_NUMBER='1' AIRFLOW_CTX_DAG_RUN_ID='scheduled__2024-01-27T00:00:00+00:00'
[2024-10-26T07:22:25.849+0000] {taskinstance.py:430} INFO - ::endgroup::
[2024-10-26T07:22:25.890+0000] {taskinstance.py:441} INFO - ::group::Post task execution logs
[2024-10-26T07:22:25.916+0000] {taskinstance.py:2905} ERROR - Task failed with exception
Traceback (most recent call last):
  File "/home/airflow/.local/lib/python3.10/site-packages/airflow/models/taskinstance.py", line 465, in _execute_task
    result = _execute_callable(context=context, **execute_callable_kwargs)
  File "/home/airflow/.local/lib/python3.10/site-packages/airflow/models/taskinstance.py", line 432, in _execute_callable
    return execute_callable(context=context, **execute_callable_kwargs)
  File "/home/airflow/.local/lib/python3.10/site-packages/airflow/models/baseoperator.py", line 401, in wrapper
    return func(self, *args, **kwargs)
  File "/home/airflow/.local/lib/python3.10/site-packages/airflow/operators/python.py", line 235, in execute
    return_value = self.execute_callable()
  File "/home/airflow/.local/lib/python3.10/site-packages/airflow/operators/python.py", line 252, in execute_callable
    return self.python_callable(*self.op_args, **self.op_kwargs)
  File "/opt/airflow/dags/transform_dim_customers.py", line 10, in transform_dim_customers
    df = staging_operator.get_data_to_pd("SELECT * FROM staging.stg_customers")
  File "/opt/airflow/plugins/postgresql_operator.py", line 14, in get_data_to_pd
    return self.hook.get_pandas_df(sql)
  File "/home/airflow/.local/lib/python3.10/site-packages/airflow/providers/common/sql/hooks/sql.py", line 262, in get_pandas_df
    with closing(self.get_conn()) as conn:
  File "/home/airflow/.local/lib/python3.10/site-packages/airflow/providers/postgres/hooks/postgres.py", line 145, in get_conn
    conn = deepcopy(self.connection or self.get_connection(conn_id))
  File "/home/airflow/.local/lib/python3.10/site-packages/airflow/hooks/base.py", line 83, in get_connection
    conn = Connection.get_connection_from_secrets(conn_id)
  File "/home/airflow/.local/lib/python3.10/site-packages/airflow/models/connection.py", line 519, in get_connection_from_secrets
    raise AirflowNotFoundException(f"The conn_id `{conn_id}` isn't defined")
airflow.exceptions.AirflowNotFoundException: The conn_id `postgres_staging` isn't defined
[2024-10-26T07:22:26.012+0000] {taskinstance.py:1206} INFO - Marking task as UP_FOR_RETRY. dag_id=e_commerce_dw_etl, task_id=transform_dim_customers, run_id=scheduled__2024-01-27T00:00:00+00:00, execution_date=20240127T000000, start_date=20241026T072225, end_date=20241026T072226
[2024-10-26T07:22:26.079+0000] {standard_task_runner.py:110} ERROR - Failed to execute job 326 for task transform_dim_customers (The conn_id `postgres_staging` isn't defined; 946)
[2024-10-26T07:22:26.124+0000] {local_task_job_runner.py:240} INFO - Task exited with return code 1
[2024-10-26T07:22:26.149+0000] {local_task_job_runner.py:222} INFO - ::endgroup::
