[2024-10-26T07:35:00.124+0000] {local_task_job_runner.py:120} INFO - ::group::Pre task execution logs
[2024-10-26T07:35:00.166+0000] {taskinstance.py:2076} INFO - Dependencies all met for dep_context=non-requeueable deps ti=<TaskInstance: e_commerce_dw_etl.transform_dim_payments manual__2024-10-26T07:34:58.987236+00:00 [queued]>
[2024-10-26T07:35:00.179+0000] {taskinstance.py:2076} INFO - Dependencies all met for dep_context=requeueable deps ti=<TaskInstance: e_commerce_dw_etl.transform_dim_payments manual__2024-10-26T07:34:58.987236+00:00 [queued]>
[2024-10-26T07:35:00.180+0000] {taskinstance.py:2306} INFO - Starting attempt 1 of 1
[2024-10-26T07:35:00.204+0000] {taskinstance.py:2330} INFO - Executing <Task(PythonOperator): transform_dim_payments> on 2024-10-26 07:34:58.987236+00:00
[2024-10-26T07:35:00.215+0000] {standard_task_runner.py:63} INFO - Started process 491 to run task
[2024-10-26T07:35:00.219+0000] {standard_task_runner.py:90} INFO - Running: ['***', 'tasks', 'run', 'e_commerce_dw_etl', 'transform_dim_payments', 'manual__2024-10-26T07:34:58.987236+00:00', '--job-id', '689', '--raw', '--subdir', 'DAGS_FOLDER/e_commerce_dw_dag.py', '--cfg-path', '/tmp/tmptrb6x1tp']
[2024-10-26T07:35:00.222+0000] {standard_task_runner.py:91} INFO - Job 689: Subtask transform_dim_payments
[2024-10-26T07:35:00.291+0000] {task_command.py:426} INFO - Running <TaskInstance: e_commerce_dw_etl.transform_dim_payments manual__2024-10-26T07:34:58.987236+00:00 [running]> on host eed3011aebc3
[2024-10-26T07:35:00.415+0000] {taskinstance.py:2648} INFO - Exporting env vars: AIRFLOW_CTX_DAG_OWNER='***' AIRFLOW_CTX_DAG_ID='e_commerce_dw_etl' AIRFLOW_CTX_TASK_ID='transform_dim_payments' AIRFLOW_CTX_EXECUTION_DATE='2024-10-26T07:34:58.987236+00:00' AIRFLOW_CTX_TRY_NUMBER='1' AIRFLOW_CTX_DAG_RUN_ID='manual__2024-10-26T07:34:58.987236+00:00'
[2024-10-26T07:35:00.416+0000] {taskinstance.py:430} INFO - ::endgroup::
[2024-10-26T07:35:00.451+0000] {base.py:84} INFO - Using connection ID 'postgres' for task execution.
[2024-10-26T07:35:00.483+0000] {logging_mixin.py:188} WARNING - /home/***/.local/lib/python3.10/site-packages/***/providers/common/sql/hooks/sql.py:263 UserWarning: pandas only supports SQLAlchemy connectable (engine/connection) or database string URI or sqlite3 DBAPI2 connection. Other DBAPI2 objects are not tested. Please consider using SQLAlchemy.
[2024-10-26T07:35:00.494+0000] {taskinstance.py:441} INFO - ::group::Post task execution logs
[2024-10-26T07:35:00.496+0000] {taskinstance.py:2905} ERROR - Task failed with exception
Traceback (most recent call last):
  File "/home/airflow/.local/lib/python3.10/site-packages/pandas/io/sql.py", line 2018, in execute
    cur.execute(*args, **kwargs)
psycopg2.errors.UndefinedTable: relation "staging.stg_payments" does not exist
LINE 1: SELECT * FROM staging.stg_payments
                      ^


The above exception was the direct cause of the following exception:

Traceback (most recent call last):
  File "/home/airflow/.local/lib/python3.10/site-packages/airflow/models/taskinstance.py", line 465, in _execute_task
    result = _execute_callable(context=context, **execute_callable_kwargs)
  File "/home/airflow/.local/lib/python3.10/site-packages/airflow/models/taskinstance.py", line 432, in _execute_callable
    return execute_callable(context=context, **execute_callable_kwargs)
  File "/home/airflow/.local/lib/python3.10/site-packages/airflow/models/baseoperator.py", line 401, in wrapper
    return func(self, *args, **kwargs)
  File "/home/airflow/.local/lib/python3.10/site-packages/airflow/operators/python.py", line 235, in execute
    return_value = self.execute_callable()
  File "/home/airflow/.local/lib/python3.10/site-packages/airflow/operators/python.py", line 252, in execute_callable
    return self.python_callable(*self.op_args, **self.op_kwargs)
  File "/opt/airflow/dags/transform_dim_payments.py", line 8, in transform_dim_payments
    df = staging_operator.get_data_to_pd("SELECT * FROM staging.stg_payments")
  File "/opt/airflow/plugins/postgresql_operator.py", line 14, in get_data_to_pd
    return self.hook.get_pandas_df(sql)
  File "/home/airflow/.local/lib/python3.10/site-packages/airflow/providers/common/sql/hooks/sql.py", line 263, in get_pandas_df
    return psql.read_sql(sql, con=conn, params=parameters, **kwargs)
  File "/home/airflow/.local/lib/python3.10/site-packages/pandas/io/sql.py", line 564, in read_sql
    return pandas_sql.read_query(
  File "/home/airflow/.local/lib/python3.10/site-packages/pandas/io/sql.py", line 2078, in read_query
    cursor = self.execute(*args)
  File "/home/airflow/.local/lib/python3.10/site-packages/pandas/io/sql.py", line 2030, in execute
    raise ex from exc
pandas.errors.DatabaseError: Execution failed on sql 'SELECT * FROM staging.stg_payments': relation "staging.stg_payments" does not exist
LINE 1: SELECT * FROM staging.stg_payments
                      ^

[2024-10-26T07:35:00.520+0000] {taskinstance.py:1206} INFO - Marking task as FAILED. dag_id=e_commerce_dw_etl, task_id=transform_dim_payments, run_id=manual__2024-10-26T07:34:58.987236+00:00, execution_date=20241026T073458, start_date=20241026T073500, end_date=20241026T073500
[2024-10-26T07:35:00.541+0000] {standard_task_runner.py:110} ERROR - Failed to execute job 689 for task transform_dim_payments (Execution failed on sql 'SELECT * FROM staging.stg_payments': relation "staging.stg_payments" does not exist
LINE 1: SELECT * FROM staging.stg_payments
                      ^
; 491)
[2024-10-26T07:35:00.593+0000] {local_task_job_runner.py:240} INFO - Task exited with return code 1
[2024-10-26T07:35:00.617+0000] {taskinstance.py:3503} INFO - 0 downstream tasks scheduled from follow-on schedule check
[2024-10-26T07:35:00.619+0000] {local_task_job_runner.py:222} INFO - ::endgroup::
