[2024-10-26T06:01:08.737+0000] {local_task_job_runner.py:120} INFO - ::group::Pre task execution logs
[2024-10-26T06:01:08.795+0000] {taskinstance.py:2076} INFO - Dependencies all met for dep_context=non-requeueable deps ti=<TaskInstance: transform_and_load_to_staging.extract_and_load_to_staging scheduled__2024-10-17T00:00:00+00:00 [queued]>
[2024-10-26T06:01:08.807+0000] {taskinstance.py:2076} INFO - Dependencies all met for dep_context=requeueable deps ti=<TaskInstance: transform_and_load_to_staging.extract_and_load_to_staging scheduled__2024-10-17T00:00:00+00:00 [queued]>
[2024-10-26T06:01:08.807+0000] {taskinstance.py:2306} INFO - Starting attempt 3 of 3
[2024-10-26T06:01:08.825+0000] {taskinstance.py:2330} INFO - Executing <Task(PythonOperator): extract_and_load_to_staging> on 2024-10-17 00:00:00+00:00
[2024-10-26T06:01:08.831+0000] {standard_task_runner.py:63} INFO - Started process 456 to run task
[2024-10-26T06:01:08.834+0000] {standard_task_runner.py:90} INFO - Running: ['***', 'tasks', 'run', 'transform_and_load_to_staging', 'extract_and_load_to_staging', 'scheduled__2024-10-17T00:00:00+00:00', '--job-id', '46', '--raw', '--subdir', 'DAGS_FOLDER/extract_data.py', '--cfg-path', '/tmp/tmpvc__6veb']
[2024-10-26T06:01:08.836+0000] {standard_task_runner.py:91} INFO - Job 46: Subtask extract_and_load_to_staging
[2024-10-26T06:01:08.888+0000] {task_command.py:426} INFO - Running <TaskInstance: transform_and_load_to_staging.extract_and_load_to_staging scheduled__2024-10-17T00:00:00+00:00 [running]> on host eed3011aebc3
[2024-10-26T06:01:08.997+0000] {taskinstance.py:2648} INFO - Exporting env vars: AIRFLOW_CTX_DAG_OWNER='***' AIRFLOW_CTX_DAG_ID='transform_and_load_to_staging' AIRFLOW_CTX_TASK_ID='extract_and_load_to_staging' AIRFLOW_CTX_EXECUTION_DATE='2024-10-17T00:00:00+00:00' AIRFLOW_CTX_TRY_NUMBER='3' AIRFLOW_CTX_DAG_RUN_ID='scheduled__2024-10-17T00:00:00+00:00'
[2024-10-26T06:01:08.998+0000] {taskinstance.py:430} INFO - ::endgroup::
[2024-10-26T06:01:09.036+0000] {base.py:84} INFO - Using connection ID 'mysql' for task execution.
[2024-10-26T06:01:30.103+0000] {mysql_operator.py:13} ERROR - Can't connect to mysql database
[2024-10-26T06:01:30.114+0000] {base.py:84} INFO - Using connection ID 'mysql' for task execution.
[2024-10-26T06:01:51.168+0000] {taskinstance.py:441} INFO - ::group::Post task execution logs
[2024-10-26T06:01:51.169+0000] {taskinstance.py:2905} ERROR - Task failed with exception
Traceback (most recent call last):
  File "/home/airflow/.local/lib/python3.10/site-packages/airflow/models/taskinstance.py", line 465, in _execute_task
    result = _execute_callable(context=context, **execute_callable_kwargs)
  File "/home/airflow/.local/lib/python3.10/site-packages/airflow/models/taskinstance.py", line 432, in _execute_callable
    return execute_callable(context=context, **execute_callable_kwargs)
  File "/home/airflow/.local/lib/python3.10/site-packages/airflow/models/baseoperator.py", line 401, in wrapper
    return func(self, *args, **kwargs)
  File "/home/airflow/.local/lib/python3.10/site-packages/airflow/operators/python.py", line 235, in execute
    return_value = self.execute_callable()
  File "/home/airflow/.local/lib/python3.10/site-packages/airflow/operators/python.py", line 252, in execute_callable
    return self.python_callable(*self.op_args, **self.op_kwargs)
  File "/opt/airflow/dags/extract_data.py", line 120, in extract_and_load_to_staging
    df = source_operator.get_data_to_pd(f"SELECT * FROM {table}")
  File "/opt/airflow/plugins/mysql_operator.py", line 15, in get_data_to_pd
    return self.mysqlhook.get_pandas_df(query)
  File "/home/airflow/.local/lib/python3.10/site-packages/airflow/providers/common/sql/hooks/sql.py", line 262, in get_pandas_df
    with closing(self.get_conn()) as conn:
  File "/home/airflow/.local/lib/python3.10/site-packages/airflow/providers/mysql/hooks/mysql.py", line 196, in get_conn
    return MySQLdb.connect(**conn_config)
  File "/home/airflow/.local/lib/python3.10/site-packages/MySQLdb/__init__.py", line 121, in Connect
    return Connection(*args, **kwargs)
  File "/home/airflow/.local/lib/python3.10/site-packages/MySQLdb/connections.py", line 195, in __init__
    super().__init__(*args, **kwargs2)
MySQLdb.OperationalError: (2002, "Can't connect to server on '192.168.1.197' (115)")
[2024-10-26T06:01:51.189+0000] {taskinstance.py:1206} INFO - Marking task as FAILED. dag_id=transform_and_load_to_staging, task_id=extract_and_load_to_staging, run_id=scheduled__2024-10-17T00:00:00+00:00, execution_date=20241017T000000, start_date=20241026T060108, end_date=20241026T060151
[2024-10-26T06:01:51.204+0000] {standard_task_runner.py:110} ERROR - Failed to execute job 46 for task extract_and_load_to_staging ((2002, "Can't connect to server on '192.168.1.197' (115)"); 456)
[2024-10-26T06:01:51.251+0000] {local_task_job_runner.py:240} INFO - Task exited with return code 1
[2024-10-26T06:01:51.275+0000] {taskinstance.py:3503} INFO - 0 downstream tasks scheduled from follow-on schedule check
[2024-10-26T06:01:51.282+0000] {local_task_job_runner.py:222} INFO - ::endgroup::
