[2024-10-26T07:36:19.581+0000] {local_task_job_runner.py:120} INFO - ::group::Pre task execution logs
[2024-10-26T07:36:19.632+0000] {taskinstance.py:2076} INFO - Dependencies all met for dep_context=non-requeueable deps ti=<TaskInstance: e_commerce_dw_etl.transform_dim_customers manual__2024-10-26T07:36:18.597456+00:00 [queued]>
[2024-10-26T07:36:19.645+0000] {taskinstance.py:2076} INFO - Dependencies all met for dep_context=requeueable deps ti=<TaskInstance: e_commerce_dw_etl.transform_dim_customers manual__2024-10-26T07:36:18.597456+00:00 [queued]>
[2024-10-26T07:36:19.646+0000] {taskinstance.py:2306} INFO - Starting attempt 1 of 1
[2024-10-26T07:36:19.670+0000] {taskinstance.py:2330} INFO - Executing <Task(PythonOperator): transform_dim_customers> on 2024-10-26 07:36:18.597456+00:00
[2024-10-26T07:36:19.681+0000] {standard_task_runner.py:63} INFO - Started process 555 to run task
[2024-10-26T07:36:19.686+0000] {standard_task_runner.py:90} INFO - Running: ['***', 'tasks', 'run', 'e_commerce_dw_etl', 'transform_dim_customers', 'manual__2024-10-26T07:36:18.597456+00:00', '--job-id', '697', '--raw', '--subdir', 'DAGS_FOLDER/e_commerce_dw_dag.py', '--cfg-path', '/tmp/tmp5ua03boz']
[2024-10-26T07:36:19.689+0000] {standard_task_runner.py:91} INFO - Job 697: Subtask transform_dim_customers
[2024-10-26T07:36:19.758+0000] {task_command.py:426} INFO - Running <TaskInstance: e_commerce_dw_etl.transform_dim_customers manual__2024-10-26T07:36:18.597456+00:00 [running]> on host eed3011aebc3
[2024-10-26T07:36:19.892+0000] {taskinstance.py:2648} INFO - Exporting env vars: AIRFLOW_CTX_DAG_OWNER='***' AIRFLOW_CTX_DAG_ID='e_commerce_dw_etl' AIRFLOW_CTX_TASK_ID='transform_dim_customers' AIRFLOW_CTX_EXECUTION_DATE='2024-10-26T07:36:18.597456+00:00' AIRFLOW_CTX_TRY_NUMBER='1' AIRFLOW_CTX_DAG_RUN_ID='manual__2024-10-26T07:36:18.597456+00:00'
[2024-10-26T07:36:19.894+0000] {taskinstance.py:430} INFO - ::endgroup::
[2024-10-26T07:36:19.931+0000] {base.py:84} INFO - Using connection ID 'postgres' for task execution.
[2024-10-26T07:36:19.965+0000] {logging_mixin.py:188} WARNING - /home/***/.local/lib/python3.10/site-packages/***/providers/common/sql/hooks/sql.py:263 UserWarning: pandas only supports SQLAlchemy connectable (engine/connection) or database string URI or sqlite3 DBAPI2 connection. Other DBAPI2 objects are not tested. Please consider using SQLAlchemy.
[2024-10-26T07:36:19.997+0000] {taskinstance.py:441} INFO - ::group::Post task execution logs
[2024-10-26T07:36:20.000+0000] {taskinstance.py:2905} ERROR - Task failed with exception
Traceback (most recent call last):
  File "/home/airflow/.local/lib/python3.10/site-packages/airflow/models/taskinstance.py", line 465, in _execute_task
    result = _execute_callable(context=context, **execute_callable_kwargs)
  File "/home/airflow/.local/lib/python3.10/site-packages/airflow/models/taskinstance.py", line 432, in _execute_callable
    return execute_callable(context=context, **execute_callable_kwargs)
  File "/home/airflow/.local/lib/python3.10/site-packages/airflow/models/baseoperator.py", line 401, in wrapper
    return func(self, *args, **kwargs)
  File "/home/airflow/.local/lib/python3.10/site-packages/airflow/operators/python.py", line 235, in execute
    return_value = self.execute_callable()
  File "/home/airflow/.local/lib/python3.10/site-packages/airflow/operators/python.py", line 252, in execute_callable
    return self.python_callable(*self.op_args, **self.op_kwargs)
  File "/opt/airflow/dags/transform_dim_customers.py", line 23, in transform_dim_customers
    df['end_date'] = pd.Timestamp('9999-12-31').date()
  File "pandas/_libs/tslibs/timestamps.pyx", line 1698, in pandas._libs.tslibs.timestamps.Timestamp.__new__
  File "pandas/_libs/tslibs/conversion.pyx", line 249, in pandas._libs.tslibs.conversion.convert_to_tsobject
  File "pandas/_libs/tslibs/conversion.pyx", line 523, in pandas._libs.tslibs.conversion._convert_str_to_tsobject
  File "pandas/_libs/tslibs/conversion.pyx", line 506, in pandas._libs.tslibs.conversion._convert_str_to_tsobject
  File "pandas/_libs/tslibs/np_datetime.pyx", line 212, in pandas._libs.tslibs.np_datetime.check_dts_bounds
pandas._libs.tslibs.np_datetime.OutOfBoundsDatetime: Out of bounds nanosecond timestamp: 9999-12-31 00:00:00
[2024-10-26T07:36:20.029+0000] {taskinstance.py:1206} INFO - Marking task as FAILED. dag_id=e_commerce_dw_etl, task_id=transform_dim_customers, run_id=manual__2024-10-26T07:36:18.597456+00:00, execution_date=20241026T073618, start_date=20241026T073619, end_date=20241026T073620
[2024-10-26T07:36:20.060+0000] {standard_task_runner.py:110} ERROR - Failed to execute job 697 for task transform_dim_customers (Out of bounds nanosecond timestamp: 9999-12-31 00:00:00; 555)
[2024-10-26T07:36:20.101+0000] {local_task_job_runner.py:240} INFO - Task exited with return code 1
[2024-10-26T07:36:20.129+0000] {taskinstance.py:3503} INFO - 0 downstream tasks scheduled from follow-on schedule check
[2024-10-26T07:36:20.133+0000] {local_task_job_runner.py:222} INFO - ::endgroup::
